Workbook

Sheet Data
A1: request_id | B1: request_year | C1: request_status | D1: request_length_words | E1: dominant_topic | F1: dominant_topic_label | G1: Typology of Administration | H1: sentiment_z | I1: ASP_level | J1: sex (requester) | K1: sex (respondent)
A2: frais_de_voyage_des_cabinets_du_4 | B2: 2017 | C2: Not successful | D2: 84 | E2: T3 | F2: T3: Police & administrative authority legality | G2: 1. Local Territorial Authorities and Public Local Entities | H2: 2.354266 | I2: 4 | J2: FEMALE | K2: UNKNOWN
A3: sau_msi_drohme_procedure_dattrib | B3: 2017 | C3: Successful | D3: 73 | E3: T1 | F3: T1: Public finance oversight | G3: 5. Sectoral Agencies, Intermunicipal Organizations, and Specialized Bodies | H3: -0.08142632 | I3: 3 | J3: MALE | K3: FEMALE
A4: travaux_publics_2001_2016_3 | B4: 2017 | C4: Not successful | D4: 73 | E4: T2 | F4: T2: Urban planning & neighbourhood issues | G4: 1. Local Territorial Authorities and Public Local Entities | H4: -0.78015241 | I4: 2 | J4: FEMALE | K4: MALE
A5: composition_des_cabinets_du_bour_18 | B5: 2017 | C5: Successful | D5: 153 | E5: T1 | F5: T1: Public finance oversight | G5: 1. Local Territorial Authorities and Public Local Entities | H5: -0.38180006 | I5: 3 | J5: FEMALE | K5: MALE
A6: transparence_des_mandats_liste_d_15 | B6: 2016 | C6: Successful | D6: 87 | E6: T4 | F6: T4: Council deliberations & transparency | G6: 1. Local Territorial Authorities and Public Local Entities | H6: 0.12592813 | I6: 4 | J6: MALE | K6: FEMALE
A7: demande_de_la_liste_complete_des_2 | B7: 2017 | C7: Successful | D7: 61 | E7: T2 | F7: T2: Urban planning & neighbourhood issues | G7: 1. Local Territorial Authorities and Public Local Entities | H7: 1.2071335 | I7: 2 | J7: MALE | K7: FEMALE
A8: justificatif_du_retard_de_rectif | B8: 2017 | C8: Asleep | D8: 179 | E8: T2 | F8: T2: Urban planning & neighbourhood issues | G8: 9. Social Housing and Public Residential Institutions | H8: -0.44312731 | I8: 2 | J8: FEMALE | K8: NO_RESPONSE
A9: interdiction_de_circulation_des | B9: 2017 | C9: Asleep | D9: 95 | E9: T1 | F9: T1: Public finance oversight | G9: 10. Police, Defense, and Public Safety Structures | H9: -0.3265328 | I9: 3 | J9: FEMALE | K9: FEMALE
A10: conseil_communal_seance_du_12_ju | B10: 2017 | C10: Successful | D10: 52 | E10: T6 | F10: T6: Governance & municipal finance analysis | G10: 1. Local Territorial Authorities and Public Local Entities | H10: -0.75255121 | I10: 3 | J10: MALE | K10: UNKNOWN
A11: titre_honorifique_de_directeur_d | B11: 2018 | C11: Not successful | D11: 163 | E11: T1 | F11: T1: Public finance oversight | G11: 3. Federal Institutions and National Government Bodies | H11: 0.61922807 | I11: 3 | J11: MALE | K11: MALE
A12: composition_des_cabinets_du_bour_10 | B12: 2017 | C12: Not successful | D12: 151 | E12: T1 | F12: T1: Public finance oversight | G12: 1. Local Territorial Authorities and Public Local Entities | H12: -0.08142632 | I12: 3 | J12: FEMALE | K12: UNKNOWN
A13: liste_des_veterinaires | B13: 2017 | C13: Not successful | D13: 49 | E13: T1 | F13: T1: Public finance oversight | G13: 6. Regulatory, Supervisory, and Oversight Authorities | H13: 0.22729113 | I13: 3 | J13: UNKNOWN | K13: MALE
... A4266: enquete_du_journal_lesoir_projet_43 | B4266: 2021 | C4266: Asleep | D4266: 369 | E4266: T6 | F4266: T6: Governance & municipal finance analysis | G4266: 1. Local Territorial Authorities and Public Local Entities | H4266: 0.69311782 | I4266: 3 | J4266: MALE | K4266: FEMALE

Sheet Analysis
A1: CROSS-GENDER ANALYSIS
A3: SECTION 1: Dataset Overview
A4: Metric | B4: Count | C4: Formula
A5: Total requests | B5: =COUNTA(Data!A2:A10000) -> 4265 | C5: Counts all non-empty request_id cells
A6: Requests with response (col K not blank) | B6: =COUNTA(Data!K2:L10000) -> 4265 | C6: Counts non-empty cells in sex (respondent)
A7: Requests WITHOUT response (col K blank) | B7: =COUNTBLANK(Data!K2:L4274) -> 4281 | C7: Blank cells in col K (rows 2-4274)
A9: Requester gender known (col J not UNKNOWN*) | B9: =COUNTIFS(Data!J2:J10000,"MALE")+COUNTIFS(Data!J2:J10000,"FEMALE") -> 3825 | C9: MALE + FEMALE in col J
A10: Requester gender UNKNOWN (col J) | B10: =COUNTIFS(Data!J2:J10000,"UNKNOWN") -> 440 | C10: UNKNOWN in col J
A11: Requester gender known BUT no response data (col K blank) | B11: =SUMPRODUCT((Data!J2:J4274<>"UNKNOWN")*(Data!K2:L4274=""))+SUMPRODUCT((Data!J2:J4274<>"UNKNOWN")*(ISBLANK(Data!K2:L4274))) -> 7682 | C11: Requester is MALE or FEMALE but col K is empty — no response to analyze
A12: Respondent gender known (col K is MALE or FEMALE) | B12: =COUNTIFS(Data!K2:L10000,"MALE")+COUNTIFS(Data!K2:L10000,"FEMALE") -> 1293 | C12: MALE + FEMALE inferred in col K
A13: Respondent gender UNKNOWN (any UNKNOWN category in col K) | B13: =COUNTIFS(Data!K2:L10000,"UNKNOWN*") -> 1218 | C13: All UNKNOWN variants in col K
A15: SECTION 2: Requests with BOTH genders known
A16: (Among requests that have a response, i.e. col K not blank)
A18: Metric | B18: Count | C18: % of responded requests
A19: Both requester AND respondent gender known | B19: =SUMPRODUCT((Data!J2:J4274<>"UNKNOWN")*(Data!K2:L4274<>"")*(LEFT(Data!K2:L4274,7)<>"UNKNOWN")) -> 2714 | C19: =IF(B6>0,B19/B6,"N/A") -> 0.63634232
A20: Requester known, respondent UNKNOWN | B20: =SUMPRODUCT((Data!J2:J4274<>"UNKNOWN")*(Data!K2:L4274<>"")*(LEFT(Data!K2:L4274,7)="UNKNOWN")) -> 1111 | C20: =IF(B6>0,B20/B6,"N/A") -> 0.26049238
A21: Requester UNKNOWN, respondent known | B21: =SUMPRODUCT((Data!J2:J4274="UNKNOWN")*(Data!K2:L4274<>"")*(LEFT(Data!K2:L4274,7)<>"UNKNOWN")) -> 333 | C21: =IF(B6>0,B21/B6,"N/A") -> 0.078077374
A22: Both UNKNOWN | B22: =SUMPRODUCT((Data!J2:J4274="UNKNOWN")*(Data!K2:L4274<>"")*(LEFT(Data!K2:L4274,7)="UNKNOWN")) -> 107 | C22: =IF(B6>0,B22/B6,"N/A") -> 0.025087925
A23: CHECK: sum should equal responded requests (B6) | B23: =B19+B20+B21+B22 -> 4265 | C23: =IF(B23=B6,"OK","MISMATCH!") -> OK
A25: SECTION 3: Cross-tabulation (Requester × Respondent gender)
A26: Only among the 2,517 requests that received a response. Each cell = number of requests where requester is [row gender] AND respondent is [column gender].
A28: Requester ↓ Respondent → | B28: Respondent: MALE | C28: Respondent: FEMALE | D28: Respondent: UNKNOWN* | E28: Row Total
A29: Requester: MALE | B29: =SUMPRODUCT((Data!J2:J4274="MALE")*(Data!K2:L4274="MALE")) -> 458 | C29: =SUMPRODUCT((Data!J2:J4274="MALE")*(Data!K2:L4274="FEMALE")) -> 338 | D29: =SUMPRODUCT((Data!J2:J4274="MALE")*(Data!K2:L4274<>"")*(LEFT(Data!K2:L4274,7)="UNKNOWN")) -> 767 | E29: =B29+C29+D29 -> 1563
A30: Requester: FEMALE | B30: =SUMPRODUCT((Data!J2:J4274="FEMALE")*(Data!K2:L4274="MALE")) -> 205 | C30: =SUMPRODUCT((Data!J2:J4274="FEMALE")*(Data!K2:L4274="FEMALE")) -> 200 | D30: =SUMPRODUCT((Data!J2:J4274="FEMALE")*(Data!K2:L4274<>"")*(LEFT(Data!K2:L4274,7)="UNKNOWN")) -> 344 | E30: =B30+C30+D30 -> 749
A31: Requester: UNKNOWN | B31: =SUMPRODUCT((Data!J2:J4274="UNKNOWN")*(Data!K2:L4274="MALE")) -> 52 | C31: =SUMPRODUCT((Data!J2:J4274="UNKNOWN")*(Data!K2:L4274="FEMALE")) -> 40 | D31: =SUMPRODUCT((Data!J2:J4274="UNKNOWN")*(Data!K2:L4274<>"")*(LEFT(Data!K2:L4274,7)="UNKNOWN")) -> 107 | E31: =B31+C31+D31 -> 199
A32: Column Total | B32: =B29+B30+B31 -> 715 | C32: =C29+C30+C31 -> 578 | D32: =D29+D30+D31 -> 1218 | E32: =E29+E30+E31 -> 2511
A35: SECTION 4: Respondent gender by requester gender — Does your gender affect who handles your request?
A36: Only requests with BOTH genders known (n=1,215). Each row: given requester gender, what % of respondents are male vs female? Rows sum to 100%.
A38: ALL TOPICS COMBINED
A39: Interaction | B39: Count | C39: % within requester gender | D39: Visual
A40: Male requester → Male respondent | B40: =SUMPRODUCT((Data!J2:J4274="MALE")*(Data!K2:L4274="MALE")) -> 458 | C40: =IF((B40+B41)>0, B40/(B40+B41), 0) -> 0.57537688 | D40: =REPT("█",ROUND(B40/MAX(B40:B43)*20,0)) -> ████████████████████
A41: Male requester → Female respondent | B41: =SUMPRODUCT((Data!J2:J4274="MALE")*(Data!K2:L4274="FEMALE")) -> 338 | C41: =IF((B40+B41)>0, B41/(B40+B41), 0) -> 0.42462312 | D41: =REPT("█",ROUND(B41/MAX(B40:B43)*20,0)) -> ███████████████
A42: Female requester → Male respondent | B42: =SUMPRODUCT((Data!J2:J4274="FEMALE")*(Data!K2:L4274="MALE")) -> 205 | C42: =IF((B42+B43)>0, B42/(B42+B43), 0) -> 0.50617284 | D42: =REPT("█",ROUND(B42/MAX(B40:B43)*20,0)) -> █████████
A43: Female requester → Female respondent | B43: =SUMPRODUCT((Data!J2:J4274="FEMALE")*(Data!K2:L4274="FEMALE")) -> 200 | C43: =IF((B42+B43)>0, B43/(B42+B43), 0) -> 0.49382716 | D43: =REPT("█",ROUND(B43/MAX(B40:B43)*20,0)) -> █████████
A44: Total known pairs | B44: =B40+B41+B42+B43 -> 1201
A47: BREAKDOWN BY TOPIC
A49: T1: Public finance oversight
A50: Interaction | B50: Count | C50: % within requester gender | D50: Visual
A51: Male requester → Male respondent | B51: =SUMPRODUCT((Data!E2:E4274="T1")*(Data!J2:J4274="MALE")*(Data!K2:L4274="MALE")) -> 160 | C51: =IF((B51+B52)>0, B51/(B51+B52), 0) -> 0.62015504 | D51: =IF(MAX(B51:B54)>0,REPT("█",ROUND(B51/MAX(B51:B54)*20,0)),"") -> ████████████████████
A52: Male requester → Female respondent | B52: =SUMPRODUCT((Data!E2:E4274="T1")*(Data!J2:J4274="MALE")*(Data!K2:L4274="FEMALE")) -> 98 | C52: =IF((B51+B52)>0, B52/(B51+B52), 0) -> 0.37984496 | D52: =IF(MAX(B51:B54)>0,REPT("█",ROUND(B52/MAX(B51:B54)*20,0)),"") -> ████████████
...
